Workbook

Sheet Погрешности косвенные (Шаблон)
A1: Название переменной
A2: Формулы частных производных по переменным: | B2: 1 | C2: 1 | D2: 1 | E2: 1
A3: Среднее значение переменной | B3: 1 | C3: 1 | D3: 1 | E3: 1
A4: Среднее значение функции
A5: Абсолютные погрешности переменных
A6: Относительные погрешности переменных
A7: Слагаемые | B7: =B5*B5*B2*B2 -> 0
A8: Абсолютная погрешность функции | B8: =SQRT(SUM(7:7)) -> 0
A9: Относительные погрешности функции | B9: =B8/B3 -> 0

Sheet МНК (Шаблон)
A1: x | B1: y | C1: Квадрат разности (x-xср)2 | D1: Квадрат разности (y-yср)2 | E1: Разность x-xср | F1: Разность y-yср | G1: Произведение (x-xср)(y-yср) | H1: d | I1: d2 | J1: Δy | L1: Среднее xср | M1: Среднее yср | N1: b | O1: a | P1: D | Q1: Sb2 | R1: Sa2
A2: 0.081666667 | B2: 48.691667 | C2: =(A2-$L$2)*(A2-$L$2) -> 0.67521437 | D2: =(B2-$M$2)*(B2-$M$2) -> 63998.399 | E2: =A2-$L$2 -> -0.82171429 | F2: =B2-$M$2 -> -252.97905 | G2: =E2*F2 -> 207.8765 | H2: =B2-($O$2+$N$2*A2) -> 0.42403697 | I2: =H2*H2 -> 0.17980735 | J2: =SQRT(4*$R$2+4*$Q$2*A2*A2) -> 4.9576164 | L2: =SUM(A:A)/COUNT(A:A) -> 0.90338095 | M2: =SUM(B:B)/COUNT(B:B) -> 301.67071 | N2: =SUM(G:G)/SUM(C:C) -> 308.38345 | O2: =M2-N2*L2 -> 23.082981 | P2: =SUM(C:C) -> 1.902757 | Q2: =1/P2*SUM(I:I)/(COUNT(I:I)-2) -> 5.6135134 | R2: =(1/COUNT(I:I)+L2*L2/P2)*SUM(I:I)/(COUNT(I:I)-2) -> 6.1070511
A3: 0.384 | B3: 141.54 | C3: =(A3-$L$2)*(A3-$L$2) -> 0.26975657 | D3: =(B3-$M$2)*(B3-$M$2) -> 25641.846 | E3: =A3-$L$2 -> -0.51938095 | F3: =B3-$M$2 -> -160.13071 | G3: =E3*F3 -> 83.168843 | H3: =B3-($O$2+$N$2*A3) -> 0.037774563 | I3: =H3*H3 -> 0.0014269176 | J3: =SQRT(4*$R$2+4*$Q$2*A3*A3) -> 5.2668007 | Q3: Sb | R3: Sa
A4: 0.665 | B4: 228.875 | C4: =(A4-$L$2)*(A4-$L$2) -> 0.056825478 | D4: =(B4-$M$2)*(B4-$M$2) -> 5299.216 | E4: =A4-$L$2 -> -0.23838095 | F4: =B4-$M$2 -> -72.795714 | G4: =E4*F4 -> 17.353112 | H4: =B4-($O$2+$N$2*A4) -> 0.71702571 | I4: =H4*H4 -> 0.51412587 | J4: =SQRT(4*$R$2+4*$Q$2*A4*A4) -> 5.8615653 | Q4: =SQRT(Q2) -> 2.3692854 | R4: =SQRT(R2) -> 2.4712448
A5: 0.94166667 | B5: 310.74167 | C5: =(A5-$L$2)*(A5-$L$2) -> 0.0014657959 | D5: =(B5-$M$2)*(B5-$M$2) -> 82.282177 | E5: =A5-$L$2 -> 0.038285714 | F5: =B5-$M$2 -> 9.0709524 | G5: =E5*F5 -> 0.34728789 | H5: =B5-($O$2+$N$2*A5) -> -2.7357282 | I5: =H5*H5 -> 7.4842088 | J5: =SQRT(4*$R$2+4*$Q$2*A5*A5) -> 6.6587555 | Q5: 2Sb = Δb | R5: 2Sa = Δa
A6: 1.176 | B6: 388.98 | C6: =(A6-$L$2)*(A6-$L$2) -> 0.074321145 | D6: =(B6-$M$2)*(B6-$M$2) -> 7622.9114 | E6: =A6-$L$2 -> 0.27261905 | F6: =B6-$M$2 -> 87.309286 | G6: =E6*F6 -> 23.802174 | H6: =B6-($O$2+$N$2*A6) -> 3.2380839 | I6: =H6*H6 -> 10.485187 | J6: =SQRT(4*$R$2+4*$Q$2*A6*A6) -> 7.4485986 | Q6: =Q4*2 -> 4.7385708 | R6: =R4*2 -> 4.9424897
A7: 1.4363333 | B7: 461.10167 | C7: =(A7-$L$2)*(A7-$L$2) -> 0.28403824 | D7: =(B7-$M$2)*(B7-$M$2) -> 25418.229 | E7: =A7-$L$2 -> 0.53295238 | F7: =B7-$M$2 -> 159.43095 | G7: =E7*F7 -> 84.969106 | H7: =B7-($O$2+$N$2*A7) -> -4.9227404 | I7: =H7*H7 -> 24.233373 | J7: =SQRT(4*$R$2+4*$Q$2*A7*A7) -> 8.4114278
A8: 1.639 | B8: 531.765 | C8: =(A8-$L$2)*(A8-$L$2) -> 0.54113538 | D8: =(B8-$M$2)*(B8-$M$2) -> 52943.38 | E8: =A8-$L$2 -> 0.73561905 | F8: =B8-$M$2 -> 230.09429 | G8: =E8*F8 -> 169.26174 | H8: =B8-($O$2+$N$2*A8) -> 3.2415475 | I8: =H8*H8 -> 10.50763 | J8: =SQRT(4*$R$2+4*$Q$2*A8*A8) -> 9.2058134

Sheet Таблица 1
A1: Масса груза, г | B1: Положение утяжелителей
B2: 1.риска | C2: 2.риска | D2: 3.риска | E2: 4.риска | F2: 5.риска | G2: 6.риска
A3: =(47+220)/1000 -> 0.267 | B3: 5.94 | C3: 4.9 | D3: 5.38 | E3: 6.68 | F3: 7.75 | G3: 8.68
B4: 5.83 | C4: 4.7 | D4: 5.65 | E4: 6.66 | F4: 7.27 | G4: 8.2
B5: 5.96 | C5: 4.88 | D5: 5.49 | E5: 6.67 | F5: 7.83 | G5: 8.46
B6: =SUM(B3:B5)/3 -> 5.91 | C6: =SUM(C3:C5)/3 -> 4.8266667 | D6: =SUM(D3:D5)/3 -> 5.5066667 | E6: =SUM(E3:E5)/3 -> 6.67 | F6: =SUM(F3:F5)/3 -> 7.6166667 | G6: =SUM(G3:G5)/3 -> 8.4466667
A7: =(47+220*2)/1000 -> 0.487 | B7: 3.09 | C7: 3.42 | D7: 4.2 | E7: 4.71 | F7: 5.68 | G7: 5.64
B8: 3.04 | C8: 3.57 | D8: 4.07 | E8: 4.96 | F8: 5.47 | G8: 5.84
B9: 2.89 | C9: 3.54 | D9: 4.31 | E9: 4.73 | F9: 5.78 | G9: 5.49
B10: =SUM(B7:B9)/3 -> 3.0066667 | C10: =SUM(C7:C9)/3 -> 3.51 | D10: =SUM(D7:D9)/3 -> 4.1933333 | E10: =SUM(E7:E9)/3 -> 4.8 | F10: =SUM(F7:F9)/3 -> 5.6433333 | G10: =SUM(G7:G9)/3 -> 5.6566667
A11: =(47+220*3)/1000 -> 0.707 | B11: 2.42 | C11: 2.86 | D11: 3.45 | E11: 4.01 | F11: 4.6 | G11: 4.98
B12: 2.52 | C12: 2.75 | D12: 3.52 | E12: 4.21 | F12: 4.67 | G12: 4.95
B13: 2.42 | C13: 2.9 | D13: 3.38 | E13: 4.18 | F13: 4.5 | G13: 5.23
B14: =SUM(B11:B13)/3 -> 2.4533333 | C14: =SUM(C11:C13)/3 -> 2.8366667 | D14: =SUM(D11:D13)/3 -> 3.45 | E14: =SUM(E11:E13)/3 -> 4.1333333 | F14: =SUM(F11:F13)/3 -> 4.59 | G14: =SUM(G11:G13)/3 -> 5.0533333
A15: =(47+220*4)/1000 -> 0.927 | B15: 2.12 | C15: 2.64 | D15: 3.17 | E15: 3.49 | F15: 4.18 | G15: 4.79
B16: 2.31 | C16: 2.3 | D16: 2.98 | E16: 3.68 | F16: 4.06 | G16: 4.71
B17: 2.4 | C17: 2.53 | D17: 3.12 | E17: 3.51 | F17: 4.14 | G17: 4.31
B18: =SUM(B15:B17)/3 -> 2.2766667 | C18: =SUM(C15:C17)/3 -> 2.49 | D18: =SUM(D15:D17)/3 -> 3.09 | E18: =SUM(E15:E17)/3 -> 3.56 | F18: =SUM(F15:F17)/3 -> 4.1266667 | G18: =SUM(G15:G17)/3 -> 4.6033333

Sheet Таблица 2
A2: Масса груза, г | B2: tср, с | C2: a, м/с2 | D2: ε, с-2 | E2: M, Н*м
A3: ='Таблица 1'!A3 -> 0.267 | B3: ='Таблица 1'!B6 -> 5.91 | C3: ='Параметры установки'!$A$2*2/B3/B3 -> 0.040082341 | D3: =2*C3/'Параметры установки'!$B$2 -> 1.7427105 | E3: =$A$3*'Параметры установки'!$B$2/2*(9.8-C3) -> 0.059935654
B4: ='Таблица 1'!C6 -> 4.8266667 | C4: ='Параметры установки'!$A$2*2/B4/B4 -> 0.060094319 | D4: =2*C4/'Параметры установки'!$B$2 -> 2.6127965 | E4: =$A$3*'Параметры установки'!$B$2/2*(9.8-C4) -> 0.059812761
B5: ='Таблица 1'!D6 -> 5.5066667 | C5: ='Параметры установки'!$A$2*2/B5/B5 -> 0.046168999 | D5: =2*C5/'Параметры установки'!$B$2 -> 2.0073478 | E5: =$A$3*'Параметры установки'!$B$2/2*(9.8-C5) -> 0.059898276
B6: ='Таблица 1'!E6 -> 6.67 | C6: ='Параметры установки'!$A$2*2/B6/B6 -> 0.031468524 | D6: =2*C6/'Параметры установки'!$B$2 -> 1.3681967 | E6: =$A$3*'Параметры установки'!$B$2/2*(9.8-C6) -> 0.059988552
B7: ='Таблица 1'!F6 -> 7.6166667 | C7: ='Параметры установки'!$A$2*2/B7/B7 -> 0.024132268 | D7: =2*C7/'Параметры установки'!$B$2 -> 1.049229 | E7: =$A$3*'Параметры установки'!$B$2/2*(9.8-C7) -> 0.060033604
B8: ='Таблица 1'!G6 -> 8.4466667 | C8: ='Параметры установки'!$A$2*2/B8/B8 -> 0.019622635 | D8: =2*C8/'Параметры установки'!$B$2 -> 0.85315804 | E8: =$A$3*'Параметры установки'!$B$2/2*(9.8-C8) -> 0.060061297
A9: ='Таблица 1'!A7 -> 0.487 | B9: ='Таблица 1'!B10 -> 3.0066667 | C9: ='Параметры установки'!$A$2*2/B9/B9 -> 0.1548665 | D9: =2*C9/'Параметры установки'!$B$2 -> 6.7333259 | E9: =$A$9*'Параметры установки'!$B$2/2*(9.8-C9) -> 0.10803514
B10: ='Таблица 1'!C10 -> 3.51 | C10: ='Параметры установки'!$A$2*2/B10/B10 -> 0.11363544 | D10: =2*C10/'Параметры установки'!$B$2 -> 4.9406714 | E10: =$A$9*'Параметры установки'!$B$2/2*(9.8-C10) -> 0.10849697
B11: ='Таблица 1'!D10 -> 4.1933333 | C11: ='Параметры установки'!$A$2*2/B11/B11 -> 0.079617633 | D11: =2*C11/'Параметры установки'!$B$2 -> 3.4616362 | E11: =$A$9*'Параметры установки'!$B$2/2*(9.8-C11) -> 0.108878
B12: ='Таблица 1'!E10 -> 4.8 | C12: ='Параметры установки'!$A$2*2/B12/B12 -> 0.060763889 | D12: =2*C12/'Параметры установки'!$B$2 -> 2.6419082 | E12: =$A$9*'Параметры установки'!$B$2/2*(9.8-C12) -> 0.10908918
B13: ='Таблица 1'!F10 -> 5.6433333 | C13: ='Параметры установки'!$A$2*2/B13/B13 -> 0.043959893 | D13: =2*C13/'Параметры установки'!$B$2 -> 1.9112997 | E13: =$A$9*'Параметры установки'!$B$2/2*(9.8-C13) -> 0.10927741
B14: ='Таблица 1'!G10 -> 5.6566667 | C14: ='Параметры установки'!$A$2*2/B14/B14 -> 0.043752902 | D14: =2*C14/'Параметры установки'!$B$2 -> 1.9023001 | E14: =$A$9*'Параметры установки'!$B$2/2*(9.8-C14) -> 0.10927972
A15: ='Таблица 1'!A11 -> 0.707 | B15: ='Таблица 1'!B14 -> 2.4533333 | C15: ='Параметры установки'!$A$2*2/B15/B15 -> 0.23260279 | D15: =2*C15/'Параметры установки'!$B$2 -> 10.113165 | E15: =$A$15*'Параметры установки'!$B$2/2*(9.8-C15) -> 0.15557545
B16: ='Таблица 1'!C14 -> 2.8366667 | C16: ='Параметры установки'!$A$2*2/B16/B16 -> 0.17398485 | D16: =2*C16/'Параметры установки'!$B$2 -> 7.5645586 | E16: =$A$15*'Параметры установки'!$B$2/2*(9.8-C16) -> 0.15652863
B17: ='Таблица 1'!D14 -> 3.45 | C17: ='Параметры установки'!$A$2*2/B17/B17 -> 0.11762235 | D17: =2*C17/'Параметры установки'!$B$2 -> 5.1140151 | E17: =$A$15*'Параметры установки'!$B$2/2*(9.8-C17) -> 0.15744514
B18: ='Таблица 1'!E14 -> 4.1333333 | C18: ='Параметры установки'!$A$2*2/B18/B18 -> 0.08194589 | D18: =2*C18/'Параметры установки'!$B$2 -> 3.5628648 | E18: =$A$15*'Параметры установки'!$B$2/2*(9.8-C18) -> 0.15802528
B19: ='Таблица 1'!F14 -> 4.59 | C19: ='Параметры установки'!$A$2*2/B19/B19 -> 0.066451175 | D19: =2*C19/'Параметры установки'!$B$2 -> 2.8891815 | E19: =$A$15*'Параметры установки'!$B$2/2*(9.8-C19) -> 0.15827724
B20: ='Таблица 1'!G14 -> 5.0533333 | C20: ='Параметры установки'!$A$2*2/B20/B20 -> 0.05482418 | D20: =2*C20/'Параметры установки'!$B$2 -> 2.38366 | E20: =$A$15*'Параметры установки'!$B$2/2*(9.8-C20) -> 0.1584663
A21: ='Таблица 1'!A15 -> 0.927 | B21: ='Таблица 1'!B18 -> 2.2766667 | C21: ='Параметры установки'!$A$2*2/B21/B21 -> 0.27010283 | D21: =2*C21/'Параметры установки'!$B$2 -> 11.743601 | E21: =$A$21*'Параметры установки'!$B$2/2*(9.8-C21) -> 0.20318694
B22: ='Таблица 1'!C18 -> 2.49 | C22: ='Параметры установки'!$A$2*2/B22/B22 -> 0.22580281 | D22: =2*C22/'Параметры установки'!$B$2 -> 9.8175135 | E22: =$A$21*'Параметры установки'!$B$2/2*(9.8-C22) -> 0.20413146
B23: ='Таблица 1'!D18 -> 3.09 | C23: ='Параметры установки'!$A$2*2/B23/B23 -> 0.14662603 | D23: =2*C23/'Параметры установки'!$B$2 -> 6.3750448 | E23: =$A$21*'Параметры установки'!$B$2/2*(9.8-C23) -> 0.20581959
B24: ='Таблица 1'!E18 -> 3.56 | C24: ='Параметры установки'!$A$2*2/B24/B24 -> 0.11046585 | D24: =2*C24/'Параметры установки'!$B$2 -> 4.8028631 | E24: =$A$21*'Параметры установки'!$B$2/2*(9.8-C24) -> 0.20659056
B25: ='Таблица 1'!F18 -> 4.1266667 | C25: ='Параметры установки'!$A$2*2/B25/B25 -> 0.082210872 | D25: =2*C25/'Параметры установки'!$B$2 -> 3.5743857 | E25: =$A$21*'Параметры установки'!$B$2/2*(9.8-C25) -> 0.20719298
B26: ='Таблица 1'!G18 -> 4.6033333 | C26: ='Параметры установки'!$A$2*2/B26/B26 -> 0.066066787 | D26: =2*C26/'Параметры установки'!$B$2 -> 2.872469 | E26: =$A$21*'Параметры установки'!$B$2/2*(9.8-C26) -> 0.20753719

Sheet Таблица 3
A1: Номера рисок | B1: 1 | C1: 2 | D1: 3 | E1: 4 | F1: 5 | G1: 6
A2: R | B2: ='Параметры установки'!$C$2+(B1-1)*'Параметры установки'!$D$2+'Параметры установки'!$E$2/2 -> 0.077 | C2: ='Параметры установки'!$C$2+(C1-1)*'Параметры установки'!$D$2+'Параметры установки'!$E$2/2 -> 0.102 | D2: ='Параметры установки'!$C$2+(D1-1)*'Параметры установки'!$D$2+'Параметры установки'!$E$2/2 -> 0.127 | E2: ='Параметры установки'!$C$2+(E1-1)*'Параметры установки'!$D$2+'Параметры установки'!$E$2/2 -> 0.152 | F2: ='Параметры установки'!$C$2+(F1-1)*'Параметры установки'!$D$2+'Параметры установки'!$E$2/2 -> 0.177 | G2: ='Параметры установки'!$C$2+(G1-1)*'Параметры установки'!$D$2+'Параметры установки'!$E$2/2 -> 0.202
A3: R2 | B3: =B2*B2 -> 0.005929 | C3: =C2*C2 -> 0.010404 | D3: =D2*D2 -> 0.016129 | E3: =E2*E2 -> 0.023104 | F3: =F2*F2 -> 0.031329 | G3: =G2*G2 -> 0.040804
A4: I | B4: ='МНК рис.1'!N2 -> 0.013615049 | C4: ='МНК рис.2'!N2 -> 0.01982881 | D4: ='МНК рис.3'!N2 -> 0.032880793 | E4: ='МНК рис.4'!N2 -> 0.043382941 | F4: ='МНК рис.5'!N2 -> 0.057094154 | G4: ='МНК рис.6'!N2 -> 0.07198726

Sheet График 1

Sheet График 2

Sheet Печать 1
A1: Таблица 1. Протокол измерений времени падения груза при разной массе груза и разном положении утяжелителей на крестовине
A2: Масса груза, кг | B2: Положение утяжелителей
B3: 1.риска | C3: 2.риска | D3: 3.риска | E3: 4.риска | F3: 5.риска | G3: 6.риска
A4: =0.047+0.22 -> 0.267 | B4: 4.2 | C4: 4.97 | D4: 6 | E4: 6.86 | F4: 7.78 | G4: 8.88
B5: 4.3 | C5: 4.87 | D5: 5.93 | E5: 6.87 | F5: 7.8 | G5: 8.94
B6: 4.36 | C6: 4.95 | D6: 6.04 | E6: 6.96 | F6: 7.91 | G6: 9.02
B7: =SUM(B4:B6)/3 -> 4.2866667 | C7: =SUM(C4:C6)/3 -> 4.93 | D7: =SUM(D4:D6)/3 -> 5.99 | E7: =SUM(E4:E6)/3 -> 6.8966667 | F7: =SUM(F4:F6)/3 -> 7.83 | G7: =SUM(G4:G6)/3 -> 8.9466667
A8: =0.047+0.22*2 -> 0.487 | B8: 3.27 | C8: 3.52 | D8: 4.36 | E8: 4.99 | F8: 5.67 | G8: 6.36
B9: 3.18 | C9: 3.63 | D9: 4.35 | E9: 5.02 | F9: 5.74 | G9: 6.39
B10: 3.13 | C10: 3.64 | D10: 4.17 | E10: 4.96 | F10: 5.65 | G10: 6.37
B11: =SUM(B8:B10)/3 -> 3.1933333 | C11: =SUM(C8:C10)/3 -> 3.5966667 | D11: =SUM(D8:D10)/3 -> 4.2933333 | E11: =SUM(E8:E10)/3 -> 4.99 | F11: =SUM(F8:F10)/3 -> 5.6866667 | G11: =SUM(G8:G10)/3 -> 6.3733333
A12: =0.047+0.22*3 -> 0.707 | B12: 2.51 | C12: 2.94 | D12: 3.45 | E12: 4.14 | F12: 4.64 | G12: 5.24
B13: 2.56 | C13: 2.93 | D13: 3.55 | E13: 4.08 | F13: 4.75 | G13: 5.27
B14: 2.53 | C14: 3.02 | D14: 3.49 | E14: 4.07 | F14: 4.62 | G14: 5.28
B15: =SUM(B12:B14)/3 -> 2.5333333 | C15: =SUM(C12:C14)/3 -> 2.9633333 | D15: =SUM(D12:D14)/3 -> 3.4966667 | E15: =SUM(E12:E14)/3 -> 4.0966667 | F15: =SUM(F12:F14)/3 -> 4.67 | G15: =SUM(G12:G14)/3 -> 5.2633333
A16: =0.047+0.22*4 -> 0.927 | B16: 2.23 | C16: 2.59 | D16: 3.1 | E16: 3.55 | F16: 4.06 | G16: 4.61
B17: 2.23 | C17: 2.59 | D17: 3.06 | E17: 3.56 | F17: 4.01 | G17: 4.56
B18: 2.12 | C18: 2.46 | D18: 3.09 | E18: 3.58 | F18: 4.07 | G18: 4.68
B19: =SUM(B16:B18)/3 -> 2.1933333 | C19: =SUM(C16:C18)/3 -> 2.5466667 | D19: =SUM(D16:D18)/3 -> 3.0833333 | E19: =SUM(E16:E18)/3 -> 3.5633333 | F19: =SUM(F16:F18)/3 -> 4.0466667 | G19: =SUM(G16:G18)/3 -> 4.6166667
A20: Таблица 2. Значения ускорения каретки, углового ускорения крестовины и момента силы натяжения нити для средних значений времени
A21: Масса груза, кг | B21: tср, с | C21: a, м/с2 | D21: ε, с-2 | E21: M, Н*м
A22: 0.267 | B22: 4.2866667 | C22: 0.076188357 | D22: 3.3125373 | E22: 0.059713927
B23: 4.93 | C23: 0.057601554 | D23: 2.5044154 | E23: 0.059828069
B24: 5.99 | C24: 0.039018843 | D24: 1.6964714 | E24: 0.059942185
B25: 6.8966667 | C25: 0.029434019 | D25: 1.27974 | E25: 0.060001046
B26: 7.83 | C26: 0.022835184 | D26: 0.99283408 | E26: 0.060041569
B27: 8.9466667 | C27: 0.017490633 | D27: 0.7604623 | E27: 0.06007439
A28: 0.487 | B28: 3.1933333 | C28: 0.1372902 | D28: 5.969139 | E28: 0.10823201
B29: 3.5966667 | C29: 0.10822502 | D29: 4.7054354 | E29: 0.10855757
B30: 4.2933333 | C30: 0.075951931 | D30: 3.3022579 | E30: 0.10891906
B31: 4.99 | C31: 0.056224674 | D31: 2.444551 | E31: 0.10914003
B32: 5.6866667 | C32: 0.043292483 | D32: 1.8822819 | E32: 0.10928488
B33: 6.3733333 | C33: 0.034466308 | D33: 1.4985351 | E33: 0.10938374
A34: 0.707 | B34: 2.5333333 | C34: 0.21814404 | D34: 9.4845237 | E34: 0.15581056
B35: 2.9633333 | C35: 0.15942889 | D35: 6.9316909 | E35: 0.15676533
B36: 3.4966667 | C36: 0.11450371 | D36: 4.9784223 | E36: 0.15749586
B37: 4.0966667 | C37: 0.083419346 | D37: 3.6269281 | E37: 0.15800132
B38: 4.67 | C38: 0.064193976 | D38: 2.7910424 | E38: 0.15831394
B39: 5.2633333 | C39: 0.050536631 | D39: 2.1972448 | E39: 0.15853602
A40: 0.927 | B40: 2.1933333 | C40: 0.29101727 | D40: 12.652925 | E40: 0.20274102
...

Sheet Печать 2

Sheet Параметры установки
A1: h | B1: d | C1: l1 | D1: l0 | E1: b
A2: 0.7 | B2: 0.046 | C2: 0.057 | D2: 0.025 | E2: 0.04

Sheet Погрешности прямые (t)
A1: Значения x | B1: Квадрат разности (x-xср)2 | H1: Среднее xср | I1: СКО Sxср | J1: Коэфф. Стьюдента tα,n | K1: Доверительный интервал Δxср | L1: Инструментальная погрешность Δиx | M1: Абсолютная погрешность Δx | N1: Относительная погрешность εx
A2: ='Таблица 1'!B3 -> 5.94 | B2: =(A2-$H$2)*(A2-$H$2) -> 0.0009 | H2: =SUM(A:A)/COUNT(A:A) -> 5.91 | I2: =SQRT(SUM(B:B)/COUNT(A:A)/(COUNT(A:A)-1)) -> 0.040414519 | J2: 0.95 | K2: =J2*I2 -> 0.038393793 | L2: 1 | M2: =SQRT(K2*K2+(2/3*L2)*(2/3*L2)) -> 0.66777131 | N2: =M2/H2 -> 0.11299007
A3: ='Таблица 1'!B4 -> 5.83 | B3: =(A3-$H$2)*(A3-$H$2) -> 0.0064
A4: ='Таблица 1'!B5 -> 5.96 | B4: =(A4-$H$2)*(A4-$H$2) -> 0.0025

Sheet Погрешности прямые (a)
A1: Значения x | B1: Квадрат разности (x-xср)2 | H1: Среднее xср | I1: СКО Sxср | J1: Коэфф. Стьюдента tα,n | K1: Доверительный интервал Δxср | L1: Инструментальная погрешность Δиx | M1: Абсолютная погрешность Δx | N1: Относительная погрешность εx
A2: ='Таблица 2'!C3 -> 0.040082341 | B2: =(A2-$H$2)*(A2-$H$2) -> 9.9487232e-06 | H2: =SUM(A:A)/COUNT(A:A) -> 0.036928181 | I2: =SQRT(SUM(B:B)/COUNT(A:A)/(COUNT(A:A)-1)) -> 0.0061238239 | J2: 0.95 | K2: =J2*I2 -> 0.0058176327 | L2: 1 | M2: =SQRT(K2*K2+(2/3*L2)*(2/3*L2)) -> 0.66669205 | N2: =M2/H2 -> 18.053747
A3: ='Таблица 2'!C4 -> 0.060094319 | B3: =(A3-$H$2)*(A3-$H$2) -> 0.00053666998
A4: ='Таблица 2'!C5 -> 0.046168999 | B4: =(A4-$H$2)*(A4-$H$2) -> 8.539272e-05
A5: ='Таблица 2'!C6 -> 0.031468524 | B5: =(A5-$H$2)*(A5-$H$2) -> 2.9807858e-05
A6: ='Таблица 2'!C7 -> 0.024132268 | B6: =(A6-$H$2)*(A6-$H$2) -> 0.00016373539
A7: ='Таблица 2'!C8 -> 0.019622635 | B7: =(A7-$H$2)*(A7-$H$2) -> 0.00029948192

Sheet Погрешности косвенные (a)
A1: Название переменной | B1: a
A2: Формулы частных производных по переменным: | B2: =-4*'Параметры установки'!A2/'Погрешности прямые (t)'!H2/'Погрешности прямые (t)'!H2/'Погрешности прямые (t)'!H2 -> -0.013564244
A3: Среднее значение переменной | B3: ='Погрешности прямые (t)'!H2 -> 5.91
A4: Среднее значение функции | B4: =2*'Параметры установки'!A2/'Погрешности прямые (t)'!H2/'Погрешности прямые (t)'!H2 -> 0.040082341
A5: Абсолютные погрешности переменных | B5: ='Погрешности прямые (t)'!M2 -> 0.66777131
A6: Относительные погрешности переменных | B6: ='Погрешности прямые (t)'!N2 -> 0.11299007
A7: Слагаемые | B7: =B5*B5*B2*B2 -> 8.2043975e-05
A8: Абсолютная погрешность функции | B8: =SQRT(SUM(7:7)) -> 0.0090578129
A9: Относительные погрешности функции | B9: =B8/B4 -> 0.22598014

Sheet Погрешности прямые (e)
A1: Значения x | B1: Квадрат разности (x-xср)2 | H1: Среднее xср | I1: СКО Sxср | J1: Коэфф. Стьюдента tα,n | K1: Доверительный интервал Δxср | L1: Инструментальная погрешность Δиx | M1: Абсолютная погрешность Δx | N1: Относительная погрешность εx
A2: ='Таблица 2'!D3 -> 1.7427105 | B2: =(A2-$H$2)*(A2-$H$2) -> 0.01880666 | H2: =SUM(A:A)/COUNT(A:A) -> 1.6055731 | I2: =SQRT(SUM(B:B)/COUNT(A:A)/(COUNT(A:A)-1)) -> 0.26625321 | J2: 0.95 | K2: =J2*I2 -> 0.25294055 | L2: 1 | M2: =SQRT(K2*K2+(2/3*L2)*(2/3*L2)) -> 0.71303813 | N2: =M2/H2 -> 0.44410194
A3: ='Таблица 2'!D4 -> 2.6127965 | B3: =(A3-$H$2)*(A3-$H$2) -> 1.014499
A4: ='Таблица 2'!D5 -> 2.0073478 | B4: =(A4-$H$2)*(A4-$H$2) -> 0.16142291
A5: ='Таблица 2'!D6 -> 1.3681967 | B5: =(A5-$H$2)*(A5-$H$2) -> 0.056347557
A6: ='Таблица 2'!D7 -> 1.049229 | B6: =(A6-$H$2)*(A6-$H$2) -> 0.3095187
A7: ='Таблица 2'!D8 -> 0.85315804 | B7: =(A7-$H$2)*(A7-$H$2) -> 0.5661284

Sheet Погрешности косвенные (e)
A1: Название переменной | B1: ε
A2: Формулы частных производных по переменным: | B2: =-8*'Параметры установки'!A2/'Параметры установки'!B2/'Погрешности прямые (t)'!H2/'Погрешности прямые (t)'!H2/'Погрешности прямые (t)'!H2 -> -0.58974973
A3: Среднее значение переменной | B3: ='Погрешности прямые (t)'!H2 -> 5.91
A4: Среднее значение функции | B4: =4*'Параметры установки'!A2/'Параметры установки'!B2/'Погрешности прямые (t)'!H2/'Погрешности прямые (t)'!H2 -> 1.7427105
A5: Абсолютные погрешности переменных | B5: ='Погрешности прямые (t)'!M2 -> 0.66777131
A6: Относительные погрешности переменных | B6: ='Погрешности прямые (t)'!N2 -> 0.11299007
A7: Слагаемые | B7: =B5*B5*B2*B2 -> 0.15509258
A8: Абсолютная погрешность функции | B8: =SQRT(SUM(7:7)) -> 0.39381795
A9: Относительные погрешности функции | B9: =B8/B4 -> 0.22598014

Sheet Погрешности прямые (M)
A1: Значения x | B1: Квадрат разности (x-xср)2 | H1: Среднее xср | I1: СКО Sxср | J1: Коэфф. Стьюдента tα,n | K1: Доверительный интервал Δxср | L1: Инструментальная погрешность Δиx | M1: Абсолютная погрешность Δx | N1: Относительная погрешность εx
A2: ='Таблица 2'!E3 -> 0.059935654 | B2: =(A2-$H$2)*(A2-$H$2) -> 3.7518507e-10 | H2: =SUM(A:A)/COUNT(A:A) -> 0.059955024 | I2: =SQRT(SUM(B:B)/COUNT(A:A)/(COUNT(A:A)-1)) -> 3.7606403e-05 | J2: 0.95 | K2: =J2*I2 -> 3.5726083e-05 | L2: 1 | M2: =SQRT(K2*K2+(2/3*L2)*(2/3*L2)) -> 0.66666667 | N2: =M2/H2 -> 11.119446
A3: ='Таблица 2'!E4 -> 0.059812761 | B3: =(A3-$H$2)*(A3-$H$2) -> 2.0238834e-08
A4: ='Таблица 2'!E5 -> 0.059898276 | B4: =(A4-$H$2)*(A4-$H$2) -> 3.2203201e-09
A5: ='Таблица 2'!E6 -> 0.059988552 | B5: =(A5-$H$2)*(A5-$H$2) -> 1.1241104e-09
A6: ='Таблица 2'!E7 -> 0.060033604 | B6: =(A6-$H$2)*(A6-$H$2) -> 6.1747696e-09
A7: ='Таблица 2'!E8 -> 0.060061297 | B7: =(A7-$H$2)*(A7-$H$2) -> 1.1294027e-08

Sheet Погрешности косвенные (M)
A1: Название переменной | B1: M
A2: Формулы частных производных по переменным: | B2: =2*'Таблица 2'!A3*'Параметры установки'!B2*'Параметры установки'!A2/'Погрешности прямые (t)'!H2/'Погрешности прямые (t)'!H2/'Погрешности прямые (t)'!H2 -> 8.3298021e-05
A3: Среднее значение переменной | B3: ='Погрешности прямые (t)'!H2 -> 5.91
A4: Среднее значение функции | B4: ='Таблица 2'!A3*'Параметры установки'!B2/2*(9.82-2*'Параметры установки'!A2/'Погрешности прямые (t)'!H2/'Погрешности прямые (t)'!H2) -> 0.060058474
A5: Абсолютные погрешности переменных | B5: ='Погрешности прямые (t)'!M2 -> 0.66777131
A6: Относительные погрешности переменных | B6: ='Погрешности прямые (t)'!N2 -> 0.11299007
A7: Слагаемые | B7: =B5*B5*B2*B2 -> 3.0940326e-09
A8: Абсолютная погрешность функции | B8: =SQRT(SUM(7:7)) -> 5.5624029e-05
A9: Относительные погрешности функции | B9: =B8/B3 -> 9.4118493e-06

Sheet МНК рис.1
A1: x | B1: y | C1: Квадрат разности (x-xср)2 | D1: Квадрат разности (y-yср)2 | E1: Разность x-xср | F1: Разность y-yср | G1: Произведение (x-xср)(y-yср) | H1: d | I1: d2 | J1: Δy | L1: Среднее xср | M1: Среднее yср | N1: b | O1: a | P1: D | Q1: Sb2 | R1: Sa2
A2: ='Таблица 2'!D3 -> 1.7427105 | B2: ='Таблица 2'!E3 -> 0.059935654 | C2: =(A2-$L$2)*(A2-$L$2) -> 34.111325 | D2: =(B2-$M$2)*(B2-$M$2) -> 0.0051477239 | E2: =A2-$L$2 -> -5.8404901 | F2: =B2-$M$2 -> -0.07174764 | G2: =E2*F2 -> 0.41904139 | H2: =B2-($O$2+$N$2*A2) -> 0.0077709221 | I2: =H2*H2 -> 6.038723e-05 | J2: =SQRT(4*$R$2+4*$Q$2*A2*A2) -> 0.037186377 | L2: =SUM(A:A)/COUNT(A:A) -> 7.5832006 | M2: =SUM(B:B)/COUNT(B:B) -> 0.13168329 | N2: =SUM(G:G)/SUM(C:C) -> 0.013615049 | O2: =M2-N2*L2 -> 0.028437643 | P2: =SUM(C:C) -> 58.543265 | Q2: =1/P2*SUM(I:I)/(COUNT(I:I)-2) -> 4.5985214e-06 | R2: =(1/COUNT(I:I)+L2*L2/P2)*SUM(I:I)/(COUNT(I:I)-2) -> 0.00033174077
A3: ='Таблица 2'!D9 -> 6.7333259 | B3: ='Таблица 2'!E9 -> 0.10803514 | C3: =(A3-$L$2)*(A3-$L$2) -> 0.72228706 | D3: =(B3-$M$2)*(B3-$M$2) -> 0.0005592352 | E3: =A3-$L$2 -> -0.84987473 | F3: =B3-$M$2 -> -0.023648154 | G3: =E3*F3 -> 0.020097969 | H3: =B3-($O$2+$N$2*A3) -> -0.012077068 | I3: =H3*H3 -> 0.00014585556 | J3: =SQRT(4*$R$2+4*$Q$2*A3*A3) -> 0.04648557 | N3: I | O3: Mтр | Q3: Sb | R3: Sa
A4: ='Таблица 2'!D15 -> 10.113165 | B4: ='Таблица 2'!E15 -> 0.15557545 | C4: =(A4-$L$2)*(A4-$L$2) -> 6.4007183 | D4: =(B4-$M$2)*(B4-$M$2) -> 0.0005708349 | E4: =A4-$L$2 -> 2.5299641 | F4: =B4-$M$2 -> 0.023892151 | G4: =E4*F4 -> 0.060446285 | H4: =B4-($O$2+$N$2*A4) -> -0.010553435 | I4: =H4*H4 -> 0.00011137499 | J4: =SQRT(4*$R$2+4*$Q$2*A4*A4) -> 0.056641314 | Q4: =SQRT(Q2) -> 0.0021444163 | R4: =SQRT(R2) -> 0.018213752
A5: ='Таблица 2'!D21 -> 11.743601 | B5: ='Таблица 2'!E21 -> 0.20318694 | C5: =(A5-$L$2)*(A5-$L$2) -> 17.308935 | D5: =(B5-$M$2)*(B5-$M$2) -> 0.005112771 | E5: =A5-$L$2 -> 4.1604008 | F5: =B5-$M$2 -> 0.071503643 | G5: =E5*F5 -> 0.29748381 | H5: =B5-($O$2+$N$2*A5) -> 0.014859581 | I5: =H5*H5 -> 0.00022080713 | J5: =SQRT(4*$R$2+4*$Q$2*A5*A5) -> 0.062158921 | Q5: 2Sb = Δb | R5: 2Sa = Δa
Q6: =Q4*2 -> 0.0042888327 | R6: =R4*2 -> 0.036427505

Sheet МНК рис.2
A1: x | B1: y | C1: Квадрат разности (x-xср)2 | D1: Квадрат разности (y-yср)2 | E1: Разность x-xср | F1: Разность y-yср | G1: Произведение (x-xср)(y-yср) | H1: d | I1: d2 | J1: Δy | L1: Среднее xср | M1: Среднее yср | N1: b | O1: a | P1: D | Q1: Sb2 | R1: Sa2
A2: ='Таблица 2'!D4 -> 2.6127965 | B2: ='Таблица 2'!E4 -> 0.059812761 | C2: =(A2-$L$2)*(A2-$L$2) -> 13.112282 | D2: =(B2-$M$2)*(B2-$M$2) -> 0.0052460606 | E2: =A2-$L$2 -> -3.6210885 | F2: =B2-$M$2 -> -0.072429694 | G2: =E2*F2 -> 0.26227433 | H2: =B2-($O$2+$N$2*A2) -> -0.0006278186 | I2: =H2*H2 -> 3.9415619e-07 | J2: =SQRT(4*$R$2+4*$Q$2*A2*A2) -> 0.0057273459 | L2: =SUM(A:A)/COUNT(A:A) -> 6.233885 | M2: =SUM(B:B)/COUNT(B:B) -> 0.13224246 | N2: =SUM(G:G)/SUM(C:C) -> 0.01982881 | O2: =M2-N2*L2 -> 0.0086319336 | P2: =SUM(C:C) -> 29.397769 | Q2: =1/P2*SUM(I:I)/(COUNT(I:I)-2) -> 1.5461942e-07 | R2: =(1/COUNT(I:I)+L2*L2/P2)*SUM(I:I)/(COUNT(I:I)-2) -> 7.1450815e-06
A3: ='Таблица 2'!D10 -> 4.9406714 | B3: ='Таблица 2'!E10 -> 0.10849697 | C3: =(A3-$L$2)*(A3-$L$2) -> 1.6724014 | D3: =(B3-$M$2)*(B3-$M$2) -> 0.0005638481 | E3: =A3-$L$2 -> -1.2932136 | F3: =B3-$M$2 -> -0.023745486 | G3: =E3*F3 -> 0.030707985 | H3: =B3-($O$2+$N$2*A3) -> 0.0018974013 | I3: =H3*H3 -> 3.6001319e-06 | J3: =SQRT(4*$R$2+4*$Q$2*A3*A3) -> 0.0066088963 | N3: I | O3: Mтр | Q3: Sb | R3: Sa
A4: ='Таблица 2'!D16 -> 7.5645586 | B4: ='Таблица 2'!E16 -> 0.15652863 | C4: =(A4-$L$2)*(A4-$L$2) -> 1.7706922 | D4: =(B4-$M$2)*(B4-$M$2) -> 0.0005898184 | E4: =A4-$L$2 -> 1.3306736 | F4: =B4-$M$2 -> 0.024286177 | G4: =E4*F4 -> 0.032316974 | H4: =B4-($O$2+$N$2*A4) -> -0.0020994967 | I4: =H4*H4 -> 4.4078865e-06 | J4: =SQRT(4*$R$2+4*$Q$2*A4*A4) -> 0.0079981994 | Q4: =SQRT(Q2) -> 0.00039321676 | R4: =SQRT(R2) -> 0.0026730285
A5: ='Таблица 2'!D22 -> 9.8175135 | B5: ='Таблица 2'!E22 -> 0.20413146 | C5: =(A5-$L$2)*(A5-$L$2) -> 12.842393 | D5: =(B5-$M$2)*(B5-$M$2) -> 0.0051680288 | E5: =A5-$L$2 -> 3.5836285 | F5: =B5-$M$2 -> 0.071889003 | G5: =E5*F5 -> 0.25762348 | H5: =B5-($O$2+$N$2*A5) -> 0.00082991399 | I5: =H5*H5 -> 6.8875722e-07 | J5: =SQRT(4*$R$2+4*$Q$2*A5*A5) -> 0.0093910283 | Q5: 2Sb = Δb | R5: 2Sa = Δa
Q6: =Q4*2 -> 0.00078643352 | R6: =R4*2 -> 0.0053460571

Sheet МНК рис.3
A1: x | B1: y | C1: Квадрат разности (x-xср)2 | D1: Квадрат разности (y-yср)2 | E1: Разность x-xср | F1: Разность y-yср | G1: Произведение (x-xср)(y-yср) | H1: d | I1: d2 | J1: Δy | L1: Среднее xср | M1: Среднее yср | N1: b | O1: a | P1: D | Q1: Sb2 | R1: Sa2
A2: ='Таблица 2'!D5 -> 2.0073478 | B2: ='Таблица 2'!E5 -> 0.059898276 | C2: =(A2-$L$2)*(A2-$L$2) -> 4.9825526 | D2: =(B2-$M$2)*(B2-$M$2) -> 0.005345361 | E2: =A2-$L$2 -> -2.2321632 | F2: =B2-$M$2 -> -0.073111976 | G2: =E2*F2 -> 0.16319786 | H2: =B2-($O$2+$N$2*A2) -> 0.00028332131 | I2: =H2*H2 -> 8.0270967e-08 | J2: =SQRT(4*$R$2+4*$Q$2*A2*A2) -> 0.011172626 | L2: =SUM(A:A)/COUNT(A:A) -> 4.239511 | M2: =SUM(B:B)/COUNT(B:B) -> 0.13301025 | N2: =SUM(G:G)/SUM(C:C) -> 0.032880793 | O2: =M2-N2*L2 -> -0.0063882331 | P2: =SUM(C:C) -> 10.912904 | Q2: =1/P2*SUM(I:I)/(COUNT(I:I)-2) -> 1.261847e-06 | R2: =(1/COUNT(I:I)+L2*L2/P2)*SUM(I:I)/(COUNT(I:I)-2) -> 2.6122352e-05
A3: ='Таблица 2'!D11 -> 3.4616362 | B3: ='Таблица 2'!E11 -> 0.108878 | C3: =(A3-$L$2)*(A3-$L$2) -> 0.60508915 | D3: =(B3-$M$2)*(B3-$M$2) -> 0.00058236545 | E3: =A3-$L$2 -> -0.77787476 | F3: =B3-$M$2 -> -0.024132249 | G3: =E3*F3 -> 0.018771868 | H3: =B3-($O$2+$N$2*A3) -> 0.0014448902 | I3: =H3*H3 -> 2.0877077e-06 | J3: =SQRT(4*$R$2+4*$Q$2*A3*A3) -> 0.012844138 | N3: I | O3: Mтр | Q3: Sb | R3: Sa
A4: ='Таблица 2'!D17 -> 5.1140151 | B4: ='Таблица 2'!E17 -> 0.15744514 | C4: =(A4-$L$2)*(A4-$L$2) -> 0.76475752 | D4: =(B4-$M$2)*(B4-$M$2) -> 0.00059706389 | E4: =A4-$L$2 -> 0.87450415 | F4: =B4-$M$2 -> 0.024434891 | G4: =E4*F4 -> 0.021368414 | H4: =B4-($O$2+$N$2*A4) -> -0.0043194996 | I4: =H4*H4 -> 1.8658077e-05 | J4: =SQRT(4*$R$2+4*$Q$2*A4*A4) -> 0.015378378 | Q4: =SQRT(Q2) -> 0.0011233196 | R4: =SQRT(R2) -> 0.005111003
A5: ='Таблица 2'!D23 -> 6.3750448 | B5: ='Таблица 2'!E23 -> 0.20581959 | C5: =(A5-$L$2)*(A5-$L$2) -> 4.5605047 | D5: =(B5-$M$2)*(B5-$M$2) -> 0.0053011992 | E5: =A5-$L$2 -> 2.1355338 | F5: =B5-$M$2 -> 0.072809334 | G5: =E5*F5 -> 0.1554868 | H5: =B5-($O$2+$N$2*A5) -> 0.0025912881 | I5: =H5*H5 -> 6.7147741e-06 | J5: =SQRT(4*$R$2+4*$Q$2*A5*A5) -> 0.017596059 | Q5: 2Sb = Δb | R5: 2Sa = Δa
Q6: =Q4*2 -> 0.0022466393 | R6: =R4*2 -> 0.010222006

Sheet МНК рис.4
A1: x | B1: y | C1: Квадрат разности (x-xср)2 | D1: Квадрат разности (y-yср)2 | E1: Разность x-xср | F1: Разность y-yср | G1: Произведение (x-xср)(y-yср) | H1: d | I1: d2 | J1: Δy | L1: Среднее xср | M1: Среднее yср | N1: b | O1: a | P1: D | Q1: Sb2 | R1: Sa2
A2: ='Таблица 2'!D6 -> 1.3681967 | B2: ='Таблица 2'!E6 -> 0.059988552 | C2: =(A2-$L$2)*(A2-$L$2) -> 2.9782528 | D2: =(B2-$M$2)*(B2-$M$2) -> 0.0053926759 | E2: =A2-$L$2 -> -1.7257615 | F2: =B2-$M$2 -> -0.073434841 | G2: =E2*F2 -> 0.12673102 | H2: =B2-($O$2+$N$2*A2) -> 0.0014337678 | I2: =H2*H2 -> 2.0556902e-06 | J2: =SQRT(4*$R$2+4*$Q$2*A2*A2) -> 0.013378972 | L2: =SUM(A:A)/COUNT(A:A) -> 3.0939582 | M2: =SUM(B:B)/COUNT(B:B) -> 0.13342339 | N2: =SUM(G:G)/SUM(C:C) -> 0.043382941 | O2: =M2-N2*L2 -> -0.00080161136 | P2: =SUM(C:C) -> 6.3228312 | Q2: =1/P2*SUM(I:I)/(COUNT(I:I)-2) -> 3.4355756e-06 | R2: =(1/COUNT(I:I)+L2*L2/P2)*SUM(I:I)/(COUNT(I:I)-2) -> 3.8317954e-05
A3: ='Таблица 2'!D12 -> 2.6419082 | B3: ='Таблица 2'!E12 -> 0.10908918 | C3: =(A3-$L$2)*(A3-$L$2) -> 0.20434917 | D3: =(B3-$M$2)*(B3-$M$2) -> 0.00059215373 | E3: =A3-$L$2 -> -0.45204997 | F3: =B3-$M$2 -> -0.024334209 | G3: =E3*F3 -> 0.011000278 | H3: =B3-($O$2+$N$2*A3) -> -0.0047229522 | I3: =H3*H3 -> 2.2306277e-05 | J3: =SQRT(4*$R$2+4*$Q$2*A3*A3) -> 0.015785711 | N3: I | O3: Mтр | Q3: Sb | R3: Sa
A4: ='Таблица 2'!D18 -> 3.5628648 | B4: ='Таблица 2'!E18 -> 0.15802528 | C4: =(A4-$L$2)*(A4-$L$2) -> 0.21987339 | D4: =(B4-$M$2)*(B4-$M$2) -> 0.00060525275 | E4: =A4-$L$2 -> 0.46890659 | F4: =B4-$M$2 -> 0.024601885 | G4: =E4*F4 -> 0.011535986 | H4: =B4-($O$2+$N$2*A4) -> 0.0042593384 | I4: =H4*H4 -> 1.8141963e-05 | J4: =SQRT(4*$R$2+4*$Q$2*A4*A4) -> 0.018102947 | Q4: =SQRT(Q2) -> 0.0018535306 | R4: =SQRT(R2) -> 0.0061901498
A5: ='Таблица 2'!D24 -> 4.8028631 | B5: ='Таблица 2'!E24 -> 0.20659056 | C5: =(A5-$L$2)*(A5-$L$2) -> 2.9203559 | D5: =(B5-$M$2)*(B5-$M$2) -> 0.005353434 | E5: =A5-$L$2 -> 1.7089049 | F5: =B5-$M$2 -> 0.073167165 | G5: =E5*F5 -> 0.12503572 | H5: =B5-($O$2+$N$2*A5) -> -0.00097015399 | I5: =H5*H5 -> 9.4119876e-07 | J5: =SQRT(4*$R$2+4*$Q$2*A5*A5) -> 0.021685762 | Q5: 2Sb = Δb | R5: 2Sa = Δa
Q6: =Q4*2 -> 0.0037070612 | R6: =R4*2 -> 0.0123803

Sheet МНК рис.5
A1: x | B1: y | C1: Квадрат разности (x-xср)2 | D1: Квадрат разности (y-yср)2 | E1: Разность x-xср | F1: Разность y-yср | G1: Произведение (x-xср)(y-yср) | H1: d | I1: d2 | J1: Δy | L1: Среднее xср | M1: Среднее yср | N1: b | O1: a | P1: D | Q1: Sb2 | R1: Sa2
A2: ='Таблица 2'!D7 -> 1.049229 | B2: ='Таблица 2'!E7 -> 0.060033604 | C2: =(A2-$L$2)*(A2-$L$2) -> 1.7077131 | D2: =(B2-$M$2)*(B2-$M$2) -> 0.0054260465 | E2: =A2-$L$2 -> -1.306795 | F2: =B2-$M$2 -> -0.073661703 | G2: =E2*F2 -> 0.096260743 | H2: =B2-($O$2+$N$2*A2) -> 0.00094864924 | I2: =H2*H2 -> 8.9993539e-07 | J2: =SQRT(4*$R$2+4*$Q$2*A2*A2) -> 0.014590607 | L2: =SUM(A:A)/COUNT(A:A) -> 2.356024 | M2: =SUM(B:B)/COUNT(B:B) -> 0.13369531 | N2: =SUM(G:G)/SUM(C:C) -> 0.057094154 | O2: =M2-N2*L2 -> -0.00081988922 | P2: =SUM(C:C) -> 3.6741551 | Q2: =1/P2*SUM(I:I)/(COUNT(I:I)-2) -> 7.0303251e-06 | R2: =(1/COUNT(I:I)+L2*L2/P2)*SUM(I:I)/(COUNT(I:I)-2) -> 4.54819e-05
A3: ='Таблица 2'!D13 -> 1.9112997 | B3: ='Таблица 2'!E13 -> 0.10927741 | C3: =(A3-$L$2)*(A3-$L$2) -> 0.1977797 | D3: =(B3-$M$2)*(B3-$M$2) -> 0.00059623393 | E3: =A3-$L$2 -> -0.4447243 | F3: =B3-$M$2 -> -0.024417902 | G3: =E3*F3 -> 0.010859234 | H3: =B3-($O$2+$N$2*A3) -> 0.00097325546 | I3: =H3*H3 -> 9.4722619e-07 | J3: =SQRT(4*$R$2+4*$Q$2*A3*A3) -> 0.016871769 | N3: I | O3: Mтр | Q3: Sb | R3: Sa
A4: ='Таблица 2'!D19 -> 2.8891815 | B4: ='Таблица 2'!E19 -> 0.15827724 | C4: =(A4-$L$2)*(A4-$L$2) -> 0.28425694 | D4: =(B4-$M$2)*(B4-$M$2) -> 0.0006042713 | E4: =A4-$L$2 -> 0.53315752 | F4: =B4-$M$2 -> 0.02458193 | G4: =E4*F4 -> 0.013106041 | H4: =B4-($O$2+$N$2*A4) -> -0.005858247 | I4: =H4*H4 -> 3.4319058e-05 | J4: =SQRT(4*$R$2+4*$Q$2*A4*A4) -> 0.02041241 | Q4: =SQRT(Q2) -> 0.002651476 | R4: =SQRT(R2) -> 0.006744027
A5: ='Таблица 2'!D25 -> 3.5743857 | B5: ='Таблица 2'!E25 -> 0.20719298 | C5: =(A5-$L$2)*(A5-$L$2) -> 1.4844053 | D5: =(B5-$M$2)*(B5-$M$2) -> 0.0054019082 | E5: =A5-$L$2 -> 1.2183617 | F5: =B5-$M$2 -> 0.073497675 | G5: =E5*F5 -> 0.089546755 | H5: =B5-($O$2+$N$2*A5) -> 0.0039363423 | I5: =H5*H5 -> 1.549479e-05 | J5: =SQRT(4*$R$2+4*$Q$2*A5*A5) -> 0.023263961 | Q5: 2Sb = Δb | R5: 2Sa = Δa
Q6: =Q4*2 -> 0.0053029521 | R6: =R4*2 -> 0.013488054

Sheet МНК рис.6
A1: x | B1: y | C1: Квадрат разности (x-xср)2 | D1: Квадрат разности (y-yср)2 | E1: Разность x-xср | F1: Разность y-yср | G1: Произведение (x-xср)(y-yср) | H1: d | I1: d2 | J1: Δy | L1: Среднее xср | M1: Среднее yср | N1: b | O1: a | P1: D | Q1: Sb2 | R1: Sa2
A2: ='Таблица 2'!D8 -> 0.85315804 | B2: ='Таблица 2'!E8 -> 0.060061297 | C2: =(A2-$L$2)*(A2-$L$2) -> 1.3218992 | D2: =(B2-$M$2)*(B2-$M$2) -> 0.0054427257 | E2: =A2-$L$2 -> -1.1497387 | F2: =B2-$M$2 -> -0.073774831 | G2: =E2*F2 -> 0.084821782 | H2: =B2-($O$2+$N$2*A2) -> 0.0089917105 | I2: =H2*H2 -> 8.0850858e-05 | J2: =SQRT(4*$R$2+4*$Q$2*A2*A2) -> 0.049270829 | L2: =SUM(A:A)/COUNT(A:A) -> 2.0028968 | M2: =SUM(B:B)/COUNT(B:B) -> 0.13383613 | N2: =SUM(G:G)/SUM(C:C) -> 0.07198726 | O2: =M2-N2*L2 -> -0.010346923 | P2: =SUM(C:C) -> 2.2331554 | Q2: =1/P2*SUM(I:I)/(COUNT(I:I)-2) -> 0.00011455848 | R2: =(1/COUNT(I:I)+L2*L2/P2)*SUM(I:I)/(COUNT(I:I)-2) -> 0.00052351898
A3: ='Таблица 2'!D14 -> 1.9023001 | B3: ='Таблица 2'!E14 -> 0.10927972 | C3: =(A3-$L$2)*(A3-$L$2) -> 0.010119697 | D3: =(B3-$M$2)*(B3-$M$2) -> 0.00060301703 | E3: =A3-$L$2 -> -0.10059671 | F3: =B3-$M$2 -> -0.024556405 | G3: =E3*F3 -> 0.0024702934 | H3: =B3-($O$2+$N$2*A3) -> -0.017314724 | I3: =H3*H3 -> 0.00029979966 | J3: =SQRT(4*$R$2+4*$Q$2*A3*A3) -> 0.061256084 | N3: I | O3: Mтр | Q3: Sb | R3: Sa
A4: ='Таблица 2'!D20 -> 2.38366 | B4: ='Таблица 2'!E20 -> 0.1584663 | C4: =(A4-$L$2)*(A4-$L$2) -> 0.14498062 | D4: =(B4-$M$2)*(B4-$M$2) -> 0.00060664553 | E4: =A4-$L$2 -> 0.38076321 | F4: =B4-$M$2 -> 0.024630175 | G4: =E4*F4 -> 0.0093782646 | H4: =B4-($O$2+$N$2*A4) -> -0.0027799252 | I4: =H4*H4 -> 7.727984e-06 | J4: =SQRT(4*$R$2+4*$Q$2*A4*A4) -> 0.068539663 | Q4: =SQRT(Q2) -> 0.010703199 | R4: =SQRT(R2) -> 0.022880537
A5: ='Таблица 2'!D26 -> 2.872469 | B5: ='Таблица 2'!E26 -> 0.20753719 | C5: =(A5-$L$2)*(A5-$L$2) -> 0.75615587 | D5: =(B5-$M$2)*(B5-$M$2) -> 0.0054318464 | E5: =A5-$L$2 -> 0.86957223 | F5: =B5-$M$2 -> 0.073701061 | G5: =E5*F5 -> 0.064088396 | H5: =B5-($O$2+$N$2*A5) -> 0.011102938 | I5: =H5*H5 -> 0.00012327524 | J5: =SQRT(4*$R$2+4*$Q$2*A5*A5) -> 0.076648547 | Q5: 2Sb = Δb | R5: 2Sa = Δa
Q6: =Q4*2 -> 0.021406399 | R6: =R4*2 -> 0.045761074

Sheet МНК I
A1: x | B1: y | C1: Квадрат разности (x-xср)2 | D1: Квадрат разности (y-yср)2 | E1: Разность x-xср | F1: Разность y-yср | G1: Произведение (x-xср)(y-yср) | H1: d | I1: d2 | J1: Δy | L1: Среднее xср | M1: Среднее yср | N1: b | O1: a | P1: D | Q1: Sb2 | R1: Sa2
A2: ='Таблица 3'!B3 -> 0.005929 | B2: ='Таблица 3'!B4 -> 0.013615049 | C2: =(A2-$L$2)*(A2-$L$2) -> 0.00023575043 | D2: =(B2-$M$2)*(B2-$M$2) -> 0.00068555569 | E2: =A2-$L$2 -> -0.015354167 | F2: =B2-$M$2 -> -0.026183119 | G2: =E2*F2 -> 0.00040201997 | H2: =B2-($O$2+$N$2*A2) -> -0.00023328352 | I2: =H2*H2 -> 5.4421202e-08 | J2: =SQRT(4*$R$2+4*$Q$2*A2*A2) -> 0.0022250859 | L2: =SUM(A:A)/COUNT(A:A) -> 0.021283167 | M2: =SUM(B:B)/COUNT(B:B) -> 0.039798168 | N2: =SUM(G:G)/SUM(C:C) -> 1.6900842 | O2: =M2-N2*L2 -> 0.0038278236 | P2: =SUM(C:C) -> 0.00086596927 | Q2: =1/P2*SUM(I:I)/(COUNT(I:I)-2) -> 0.0019570609 | R2: =(1/COUNT(I:I)+L2*L2/P2)*SUM(I:I)/(COUNT(I:I)-2) -> 1.1689552e-06
A3: ='Таблица 3'!C3 -> 0.010404 | B3: ='Таблица 3'!C4 -> 0.01982881 | C3: =(A3-$L$2)*(A3-$L$2) -> 0.00011835627 | D3: =(B3-$M$2)*(B3-$M$2) -> 0.00039877525 | E3: =A3-$L$2 -> -0.010879167 | F3: =B3-$M$2 -> -0.019969358 | G3: =E3*F3 -> 0.00021724997 | H3: =B3-($O$2+$N$2*A3) -> -0.0015826498 | I3: =H3*H3 -> 2.5047803e-06 | J3: =SQRT(4*$R$2+4*$Q$2*A3*A3) -> 0.0023501436 | N3: 4mут | O3: I0 | Q3: Sb | R3: Sa
A4: ='Таблица 3'!D3 -> 0.016129 | B4: ='Таблица 3'!D4 -> 0.032880793 | C4: =(A4-$L$2)*(A4-$L$2) -> 2.6565434e-05 | D4: =(B4-$M$2)*(B4-$M$2) -> 4.785007e-05 | E4: =A4-$L$2 -> -0.0051541667 | F4: =B4-$M$2 -> -0.0069173745 | G4: =E4*F4 -> 3.5653301e-05 | H4: =B4-($O$2+$N$2*A4) -> 0.0017936013 | I4: =H4*H4 -> 3.2170057e-06 | J4: =SQRT(4*$R$2+4*$Q$2*A4*A4) -> 0.00259081 | Q4: =SQRT(Q2) -> 0.044238681 | R4: =SQRT(R2) -> 0.0010811823
A5: ='Таблица 3'!E3 -> 0.023104 | B5: ='Таблица 3'!E4 -> 0.043382941 | C5: =(A5-$L$2)*(A5-$L$2) -> 3.315434e-06 | D5: =(B5-$M$2)*(B5-$M$2) -> 1.2850595e-05 | E5: =A5-$L$2 -> 0.0018208333 | F5: =B5-$M$2 -> 0.0035847727 | G5: =E5*F5 -> 6.5272736e-06 | H5: =B5-($O$2+$N$2*A5) -> 0.00050741099 | I5: =H5*H5 -> 2.5746591e-07 | J5: =SQRT(4*$R$2+4*$Q$2*A5*A5) -> 0.0029756506 | Q5: 2Sb = Δb | R5: 2Sa = Δa
A6: ='Таблица 3'!F3 -> 0.031329 | B6: ='Таблица 3'!F4 -> 0.057094154 | C6: =(A6-$L$2)*(A6-$L$2) -> 0.00010091877 | D6: =(B6-$M$2)*(B6-$M$2) -> 0.00029915112 | E6: =A6-$L$2 -> 0.010045833 | F6: =B6-$M$2 -> 0.017295986 | G6: =E6*F6 -> 0.00017375259 | H6: =B6-($O$2+$N$2*A6) -> 0.00031768112 | I6: =H6*H6 -> 1.009213e-07 | J6: =SQRT(4*$R$2+4*$Q$2*A6*A6) -> 0.0035155783 | Q6: =Q4*2 -> 0.088477361 | R6: =R4*2 -> 0.0021623646
A7: ='Таблица 3'!G3 -> 0.040804 | B7: ='Таблица 3'!G4 -> 0.07198726 | C7: =(A7-$L$2)*(A7-$L$2) -> 0.00038106293 | D7: =(B7-$M$2)*(B7-$M$2) -> 0.0010361377 | E7: =A7-$L$2 -> 0.019520833 | F7: =B7-$M$2 -> 0.032189092 | G7: =E7*F7 -> 0.00062835791 | H7: =B7-($O$2+$N$2*A7) -> -0.00080276015 | I7: =H7*H7 -> 6.4442385e-07 | J7: =SQRT(4*$R$2+4*$Q$2*A7*A7) -> 0.0042082756
